Workbook
Name Print_Area: 'LAUDO DE AVALIAÇÃO 12-12.4'!$B$1:$H$24
Name Print_Area: 'LAUDO DE AVALIAÇÃO 13'!$B$1:$G$8

Sheet CAPA DO LAUDO
B3: LAUDO DE AVALIAÇÃO Nº 435420
B7: Proponente:
B8: Processo:
B9: Agência Solicitante:
B10: Objetivo:
B11: Objeto:
B12: Local e Data:
B17: QUADRO RESUMO DA AVALIAÇÃO
B19: Proponente:
B20: Agência Solicitante:
B21: Identificação:
B22: Município:
B23: IMÓVEL
B24: Nº Matrícula | E24: Identificação | H24: Área Superficial há | K24: Área Construída m²
B27: CROQUI
B34: VALORES
B35: MATRÍCULA | F35: MERCADO R$ | J35: LIQUIDAÇÃO FORÇADA R$
B38: TOTAL
B39: OBSERVAÇÕES

Sheet FATORES
D9: HIDROGRAFIA
D10: 1,30 a 1,50 - (MUITO BOM) | E10: 1.2
D11: 1,15 a 1,29 - (BOM) | E11: 1.1
D12: 1,01 a 1,14 - (NORMAL) | E12: 1
D13: 1,00 - (REGULAR) | E13: 0.9
D14: 0,80 a 0,99 - (RUIM) | E14: 0.8
D15: 0,50 a 0,79 - (MUITO RUIM) | E15: 0.7
D17: FONTE: DESLANDES, CRISTIANO AUGUSTO - AVALIAÇÃO DE IMÓVEIS RURAIS (2002).
D18: FONTE: GLOSSÁRIO INTERNACIONAL DE HIDROLOGIA (UNESCO).
D21: BENFEITORIAS | E21: Fatores | H21: ÍNDICES DE DEPRECIAÇÃO FÍSICA E FUNCIONAL
D22: MUITO ACIMA DA MÉDIA | E22: 1.2 | H22: Depreciação Física | I22: Depreciação Funcional
D23: ACIMA DA MÉDIA | E23: 1.1 | I23: Adequada | J23: Inadequada | K23: Superada | L23: Total
D24: MÉDIA | E24: 1 | H24: Ótimo | I24: 1 | J24: 0.75 | K24: 0.5 | L24: 0.2
D25: ABAIXO DA MÉDIA | E25: 0.9 | H25: Bom | I25: 0.8 | J25: 0.6 | K25: 0.4 | L25: 0.16
D26: MUITO ABAIXO DA MÉDIA | E26: 0.8 | H26: Regular | I26: 0.6 | J26: 0.45 | K26: 0.3 | L26: 0.12
D27: SEM BENFEITORIA | E27: 0.7 | H27: Precária | I27: 0.4 | J27: 0.3 | K27: 0.2 | L27: 0.08
H28: Mau | I28: 0.2 | J28: 0.15 | K28: 0.1 | L28: 0.04
D32: Situação | E32: CARACTERÍSTICA
E33: Tipo de Estrada | F33: Trafegabilidade | G33: Fatores
D34: Ótima | E34: Pavimentada com asfalto/concreto | F34: Permanente | G34: 1.2
D35: Muito Boa | E35: Pavimentada com cascalhamento/intertravado | F35: Permanente | G35: 1.1
D36: Boa | E36: Não Pavimentada | F36: Permanente | G36: 1
D37: Desfavorável | E37: Não Pavimentada e Servidões de Passagem | F37: Problemas sérios nas Estações chuvosas | G37: 0.9
D38: Má | E38: Servidões com a presença de fechos | G38: 0.8
D39: Péssima | E39: Fechos e interceptados por córregos sem pontes | F39: Problemas sérios mesmo nas secas | G39: 0.7

Sheet UTIL_LAUDO
A1: Classe | B1: Características | C1: Fatores
A2: I | B2: Terras cultiváveis aparentemente sem problemas especiais de conservação. | C2: 1.3
A4: II | B4: Terras cultiváveis com problemas simples de conservação. | C4: 1.2
A6: III | B6: Terras cultiváveis com problemas complexos de conservação. | C6: 1.1
A8: IV | B8: Terras cultiváveis apenas ocasionalmente ou em extensão limitada, com sérios problemas de conservação. | C8: 1
A10: V | B10: Terras cultiváveis apenas em casos de algumas culturas permanentes e adaptadas em geral para pastagens ou reflorestamento, encharcamento permanente, afloramento de rochas, sem necessidade de práticas especiais de conservação. | C10: 0.9
A12: VI | B12: Terras cultiváveis apenas em casos especiais de algumas culturas permanentes e adaptadas em geral para reflorestamento, com problemas simples de conservação. | C12: 0.8
A14: VII | B14: Terras cultiváveis apenas em casos especiais de algumas culturas permanentes e adaptadas em geral para pastagem ou reflorestamento, com problemas complexos de conservação. | C14: 0.7
A16: VIII | B16: Terras impróprias para cultura, pastagem ou reflorestamento, devendo servir apenas como abrigo de fauna silvestre, como ambiente para recreação ou para fins de armazenamento de água. Áreas com qualquer tipo de restrição legal de uso ou exploração. | C16: 0.6
E18: ÍNDICES DE DEPRECIAÇÃO FÍSICA E FUNCIONAL
E19: Depreciação Física | F19: Depreciação Funcional
F20: Adequada | G20: Inadequada | H20: Superada | I20: Total
E21: Ótimo | F21: 1 | G21: 0.75 | H21: 0.5 | I21: 0.2
E22: Bom | F22: 0.8 | G22: 0.6 | H22: 0.4 | I22: 0.16
E23: Regular | F23: 0.6 | G23: 0.45 | H23: 0.3 | I23: 0.12
E24: Precária | F24: 0.4 | G24: 0.3 | H24: 0.2 | I24: 0.08
E25: Mau | F25: 0.2 | G25: 0.15 | H25: 0.1 | I25: 0.04

Sheet AREA UTIL 
O3: APP | P3: ARL
C4: =C16 -> MATRÍCULA 11.173 | O4: 13.6783 | P4: 141.8504 | Q4: =P4+O4 -> 155.5287
C5: AREA TOTAL | E5: AREA DE RESERVA LEGAL | G5: AREA DE APP | I5: ÁREA CONSTRUÍDA | N5: AU
C6: =AMOSTRAS!E6 -> 52.0343 | E6: - | G6: - | I6: - | L6: 231.63 | N6: =L6+7.12 -> 238.75 | R6: =P4+O4+N6 -> 394.2787
C7: CERTIFICADO DE CADASTRO DE IMÓVEL RURAL - CCIR | R7: =C6-R6 -> -342.2444 | S7: AR
C8: AREA TOTAL | E8: CLASSIFICAÇÃO FUNDIÁRIA | G8: MÓDULO FISCAL | I8: Nº DE MÓDULOS FISCAIS
C9: 52.0343 | E9: Pequena Propriedade | G9: 80 | I9: 0.6504
C10: CADASTRO AMBIENTAL RURAL - CAR
C11: AREA TOTAL | E11: AREA DE RESERVA LEGAL | G11: AREA DE APP | I11: ÁREA CONSOLIDADA
C12: 52.0343 | E12: 18.2121 | G12: 1.7411 | I12: 9.7929
C13: SITUAÇÃO | E13: Ativo | G13: CONDIÇÃO | I13: Aguardando Análise
C16: MATRÍCULA 11.173
C17: USO DA TERRA | F17: ÁREA (ha) | H17: % ÁREA
C18: Área de Pastagem | F18: =AMOSTRAS!E11 -> 7.23 | H18: =F18/C6 -> 0.13894681
C19: Área de Vegetação Remanescente | F19: =AMOSTRAS!E12 -> 24.8511 | H19: =AMOSTRAS!F12 -> 0.47759074
C20: Área De Reserva Legal e APP | F20: =AMOSTRAS!E13 -> 19.9532 | H20: =AMOSTRAS!F13 -> 0.38346245
C21: SOMATÓRIA | F21: =SUM(F18:G20) -> 52.0343 | H21: =SUM(H18:I20) -> 1

Sheet AMOSTRAS
B3: AVALIANDA | L3: MÉDIA DAS AMOSTRAS
B4: Proprietário(s) | E4: Mauricio Miyasaki | G4: Contato: | H4: (63) 999893050 | L4: R$/ ha = | M4: =SUM(H20+H34+H48+H62+H76+H90)/6 -> 14456.008
B5: Localização do Imóvel: | E5: Guaraí - TO | G5: Situação: | H5: Boa | L5: Alq = | M5: =M4*4.84 -> 69967.077
B6: Área do Imóvel (ha): | E6: 52.0343 | G6: Benfeitoria: | H6: Abaixo da média
C7: Hidrografia: | E7: Muito bom | G7: Data: | H7: =TODAY() -> 45842
C8: Matrícula: | E8: 11173 | G8: Outros:
B9: Nota Agronômica da Amostra
B10: Classe de Solo | E10: Área (ha) | F10: % do Imóvel | G10: Nota Agronômica
B11: IV | E11: 7.23 | F11: =E11/E6 -> 0.13894681 | G11: 1
B12: VI | E12: =32.0811-E11 -> 24.8511 | F12: =E12/E6 -> 0.47759074 | G12: 0.8
B13: VIII | E13: =18.2121+1.7411 -> 19.9532 | F13: =E13/E6 -> 0.38346245 | G13: 0.6 | K13: 2.8391 | L13: 1.8497
B14: SOMATÓRIA | E14: =SUM(E11:E13) -> 52.0343 | F14: =SUM(F11:F13) -> 1 | G14: =(F12*G12)+(F13*G13)+F11*G11 -> 0.75109687
B16: Dado Amostral 01
B17: Proprietário / Informante: | E17: Aliança Imoveis | G17: Contato: | H17: (16) 3234-9000 | K17: https://to.olx.com.br/tocantins/terrenos/fazenda-guarai-guarai-1351681214?lis=listing_1100
B18: Localização do Imóvel: | E18: Guaraí - TO | G18: Situação: | H18: Boa
B19: Área do Imóvel (ha): | E19: =3500*4.84 -> 16940 | G19: Benfeitoria: | H19: Média
C20: Valor venal: | E20: =180000000 -> 180000000 | G20: Valor R$/ha: | H20: =E20/E19 -> 10625.738 | K20: =H20*4.84 -> 51428.571
C21: Negociação: | E21: Oferta | G21: Data: | H21: =TODAY() -> 45842
C22: Hidrografia: | E22: Bom | G22: Outros:
B23: Nota Agronômica da Amostra
B24: Classe de Solo | E24: Área (ha) | F24: % do Imóvel | G24: Nota Agronômica
B25: IV | E25: =600 *4.84 -> 2904 | F25: =E25/E19 -> 0.17142857 | G25: 1
C26: VI | E26: =E19-(E25+E27) -> 8107 | F26: =E26/E19 -> 0.47857143 | G26: 0.8
B27: VIII | E27: =E19*0.35 -> 5929 | F27: =E27/E19 -> 0.35 | G27: 0.6
B28: SOMATÓRIA | E28: =SUM(E25:E27) -> 16940 | F28: =SUM(F25:F27) -> 1 | G28: =F25*G25+F26*G26+F27*G27 -> 0.76428571
B30: Dado Amostral 02
B31: Proprietário / Informante: | E31: Ruraliza Negócios | G31: Contato: | H31: (63) 99252-2282 | K31: https://to.olx.com.br/tocantins/terrenos/regiao-de-guarai-to-as-margens-da-rodovia-153-1336192281?lis=listing_1100
B32: Localização do Imóvel: | E32: Guaraí - TO | G32: Situação: | H32: Ótima
B33: Área do Imóvel (ha): | E33: 1258.4 | G33: Benfeitoria: | H33: Média
C34: Valor venal: | E34: 16900000 | G34: Valor R$/ha: | H34: =E34/E33 -> 13429.752 | K34: =H34*4.84 -> 65000
C35: Negociação: | E35: Oferta | G35: Data: | H35: =TODAY() -> 45842
C36: Hidrografia: | E36: Bom | G36: Outros:
B37: Nota Agronômica da Amostra
B38: Classe de Solo | E38: Área (ha) | F38: % do Imóvel | G38: Nota Agronômica
B39: IV | E39: 145.2 | F39: =E39/E33 -> 0.11538462 | G39: 1
C40: VI | E40: =E33-(E39+E41) -> 671.24992 | F40: =E40/E33 -> 0.53341538 | G40: 0.8
B41: VIII | E41: =E33*0.3512 -> 441.95008 | F41: =E41/E33 -> 0.3512 | G41: 0.6
B42: SOMATÓRIA | E42: =SUM(E39:E41) -> 1258.4 | F42: =F39+F41+F40 -> 1 | G42: =F41*G41+F39*G39+F40*G40 -> 0.75283692
B44: Dado Amostral 03
B45: Proprietário / Informante: | E45: Ruraliza Negócios | G45: Contato: | H45: (63) 99252-2282 | K45: https://to.olx.com.br/tocantins/terrenos/imovel-para-venda-com-430-metros-quadrados-em-zona-rural-guarai-to-1328380034?lis=listing_1100
...

Sheet QUADRO
B3: ELEMENTO | C3: ÁREA (ha) | D3: VT (R$) | E3: VT(R$/ha) | F3: CLASSE | G3: SITUAÇÃO | H3: BENFEITORIAS | I3: HIDROGRAFIA | J3: FONTE | K3: INFORMANTE | L3: CONTATO
B4: 1 | C4: =AMOSTRAS!E19 -> 16940 | D4: =AMOSTRAS!E20 -> 180000000 | E4: =D4/C4 -> 10625.738 | F4: =AMOSTRAS!G28 -> 0.76428571 | G4: 1 | H4: 1 | I4: 1.1 | J4: 0.9 | K4: =AMOSTRAS!E17 -> Aliança Imoveis | L4: =AMOSTRAS!H17 -> (16) 3234-9000
B5: 2 | C5: =AMOSTRAS!E33 -> 1258.4 | D5: =AMOSTRAS!E34 -> 16900000 | E5: =D5/C5 -> 13429.752 | F5: =AMOSTRAS!G42 -> 0.75283692 | G5: 1 | H5: 1 | I5: 1.1 | J5: 0.9 | K5: =AMOSTRAS!E31 -> Ruraliza Negócios | L5: =AMOSTRAS!H31 -> (63) 99252-2282
B6: 3 | C6: =AMOSTRAS!E47 -> 430.76 | D6: =AMOSTRAS!E48 -> 7120000 | E6: =D6/C6 -> 16528.926 | F6: =AMOSTRAS!G56 -> 0.79691573 | G6: 1 | H6: 1 | I6: 1.2 | J6: 0.9 | K6: =AMOSTRAS!E45 -> Ruraliza Negócios | L6: =AMOSTRAS!H45 -> (63) 99252-2282
B7: 4 | C7: =AMOSTRAS!E61 -> 626 | D7: =AMOSTRAS!E62 -> 10500000 | E7: =D7/C7 -> 16773.163 | F7: =AMOSTRAS!G70 -> 0.80479233 | G7: 1 | H7: 1.1 | I7: 1.1 | J7: 0.9 | K7: =AMOSTRAS!E59 -> Centro De Negócios Invistta Ltda Me | L7: =AMOSTRAS!H59 -> (63) 3215-0568
B8: 5 | C8: =AMOSTRAS!E75 -> 3533.2 | D8: =AMOSTRAS!E76 -> 60000000 | E8: =D8/C8 -> 16981.773 | F8: =AMOSTRAS!G84 -> 0.78584438 | G8: 1.1 | H8: 1 | I8: 1.2 | J8: 0.9 | K8: =AMOSTRAS!E73 -> Lider Imoveis | L8: =AMOSTRAS!H73 -> (34) 3231-0019
B9: 6 | C9: =AMOSTRAS!E89 -> 3547.72 | D9: =AMOSTRAS!E90 -> 43980000 | E9: =D9/C9 -> 12396.694 | F9: =AMOSTRAS!G98 -> 0.79173166 | G9: 1 | H9: 1 | I9: 1.1 | J9: 0.9 | K9: =AMOSTRAS!E87 -> Ruraliza Negócios | L9: =AMOSTRAS!H87 -> (63) 99252-2282

Sheet PLANILHA HOMOG
A3: Elemento | B3: Municipio | C3: Imóvel | D3: Valor do Imóvel R$ | E3: Área Total Do Imóvel (ha) | F3: Valor por hectare (R$/ha) | G3: CCU do Elemento | H3: CCU Indexado 1 | I3: Situação Elemento | J3: Situação Indexado² | K3: Benfeitorias | L3: Benfeitorias Indexado³ | M3: Hidrografia Elemento | N3: Hidrografia Indexado 4 | O3: Fator Oferta Elemento | P3: Fator Homogeneização Total (FHT) 6 | Q3: VT/ha homogeneizado 7 | R3: Amostra Saneada
A4: 1 | B4: =AMOSTRAS!E18 -> Guaraí - TO | C4: Imóvel 1 | D4: =AMOSTRAS!E20 -> 180000000 | E4: =AMOSTRAS!E19 -> 16940 | F4: =D4/E4 -> 10625.738 | G4: =AMOSTRAS!G28 -> 0.76428571 | H4: =IF(G10=" ","",$G$10-G4+1) -> 0.98681116 | I4: =QUADRO!G4 -> 1 | J4: =IF(I10=" ","",$I$10-I4+1) -> 1.1 | K4: =QUADRO!H4 -> 1 | L4: =IF(K10=" ","",$K$10-K4+1) -> 0.9 | M4: =QUADRO!I4 -> 1.1 | N4: =IF(M10=" ","",$M$10-M4+1) -> 1.1 | O4: =QUADRO!J4 -> 0.9 | P4: =TRUNC(IF(O4=" ","",H4*J4*L4*N4*O4),4) -> 0.9671 | Q4: =TRUNC(IF(F4="","",F4*P4),2) -> 10276.15 | R4: =IF(AND(Q4<=$Q$12+$Q$13,Q4>=$Q$12-$Q$13),Q4,"*") -> *
A5: 2 | B5: =AMOSTRAS!E32 -> Guaraí - TO | C5: Imóvel 2 | D5: =AMOSTRAS!E34 -> 16900000 | E5: =AMOSTRAS!E33 -> 1258.4 | F5: =D5/E5 -> 13429.752 | G5: =AMOSTRAS!G42 -> 0.75283692 | H5: =IF(G10=" ","",$G$10-G5+1) -> 0.99825995 | I5: =QUADRO!G5 -> 1 | J5: =IF(I10=" ","",$I$10-I5+1) -> 1.1 | K5: =QUADRO!H5 -> 1 | L5: =IF(K10=" ","",$K$10-K5+1) -> 0.9 | M5: =QUADRO!I5 -> 1.1 | N5: =IF(M10=" ","",$M$10-M5+1) -> 1.1 | O5: =QUADRO!J5 -> 0.9 | P5: =TRUNC(IF(O5=" ","",H5*J5*L5*N5*O5),4) -> 0.9783 | Q5: =TRUNC(IF(F5="","",F5*P5),2) -> 13138.32 | R5: =IF(AND(Q5<=$Q$12+$Q$13,Q5>=$Q$12-$Q$13),Q5,"*") -> 13138.32
A6: 3 | B6: =AMOSTRAS!E46 -> Guaraí - TO | C6: Imóvel 3 | D6: =AMOSTRAS!E48 -> 7120000 | E6: =AMOSTRAS!E47 -> 430.76 | F6: =D6/E6 -> 16528.926 | G6: =AMOSTRAS!G56 -> 0.79691573 | H6: =IF(G10=" ","",$G$10-G6+1) -> 0.95418114 | I6: =QUADRO!G6 -> 1 | J6: =IF(I10=" ","",$I$10-I6+1) -> 1.1 | K6: =QUADRO!H6 -> 1 | L6: =IF(K10=" ","",$K$10-K6+1) -> 0.9 | M6: =QUADRO!I6 -> 1.2 | N6: =IF(M10=" ","",$M$10-M6+1) -> 1 | O6: =QUADRO!J6 -> 0.9 | P6: =TRUNC(IF(O6=" ","",H6*J6*L6*N6*O6),4) -> 0.8501 | Q6: =TRUNC(IF(F6="","",F6*P6),2) -> 14051.23 | R6: =IF(AND(Q6<=$Q$12+$Q$13,Q6>=$Q$12-$Q$13),Q6,"*") -> 14051.23
A7: 4 | B7: =AMOSTRAS!E60 -> Guaraí - TO | C7: Imóvel 4 | D7: =AMOSTRAS!E62 -> 10500000 | E7: =AMOSTRAS!E61 -> 626 | F7: =D7/E7 -> 16773.163 | G7: =AMOSTRAS!G70 -> 0.80479233 | H7: =IF(G11=" ","",$G$10-G7+1) -> 0.94630454 | I7: =QUADRO!G7 -> 1 | J7: =IF(I11=" ","",$I$10-I7+1) -> 1.1 | K7: =QUADRO!H7 -> 1.1 | L7: =IF(K11=" ","",$K$10-K7+1) -> 0.8 | M7: =QUADRO!I7 -> 1.1 | N7: =IF(M11=" ","",$M$10-M7+1) -> 1.1 | O7: =QUADRO!J7 -> 0.9 | P7: =TRUNC(IF(O7=" ","",H7*J7*L7*N7*O7),4) -> 0.8244 | Q7: =TRUNC(IF(F7="","",F7*P7),2) -> 13827.79 | R7: =IF(AND(Q7<=$Q$12+$Q$13,Q7>=$Q$12-$Q$13),Q7,"*") -> 13827.79
A8: 5 | B8: =AMOSTRAS!E74 -> Presidente Kennedy - TO | C8: Imóvel 5 | D8: =AMOSTRAS!E76 -> 60000000 | E8: =AMOSTRAS!E75 -> 3533.2 | F8: =D8/E8 -> 16981.773 | G8: =AMOSTRAS!G84 -> 0.78584438 | H8: =IF(G12=" ","",$G$10-G8+1) -> 0.96525249 | I8: =QUADRO!G8 -> 1.1 | J8: =IF(I12=" ","",$I$10-I8+1) -> 1 | K8: =QUADRO!H8 -> 1 | L8: =IF(K12=" ","",$K$10-K8+1) -> 0.9 | M8: =QUADRO!I8 -> 1.2 | N8: =IF(M12=" ","",$M$10-M8+1) -> 1 | O8: =QUADRO!J8 -> 0.9 | P8: =TRUNC(IF(O8=" ","",H8*J8*L8*N8*O8),4) -> 0.7818 | Q8: =TRUNC(IF(F8="","",F8*P8),2) -> 13276.35 | R8: =IF(AND(Q8<=$Q$12+$Q$13,Q8>=$Q$12-$Q$13),Q8,"*") -> 13276.35
A9: 6 | B9: =AMOSTRAS!E88 -> Guaraí - TO | C9: Imóvel 6 | D9: =AMOSTRAS!E90 -> 43980000 | E9: =AMOSTRAS!E89 -> 3547.72 | F9: =D9/E9 -> 12396.694 | G9: =AMOSTRAS!G98 -> 0.79173166 | H9: =IF(G13=" ","",$G$10-G9+1) -> 0.95936521 | I9: =QUADRO!G9 -> 1 | J9: =IF(I13=" ","",$I$10-I9+1) -> 1.1 | K9: =QUADRO!H9 -> 1 | L9: =IF(K13=" ","",$K$10-K9+1) -> 0.9 | M9: =QUADRO!I9 -> 1.1 | N9: =IF(M13=" ","",$M$10-M9+1) -> 1.1 | O9: =QUADRO!J9 -> 0.9 | P9: =TRUNC(IF(O9=" ","",H9*J9*L9*N9*O9),4) -> 0.9402 | Q9: =TRUNC(IF(F9="","",F9*P9),2) -> 11655.37 | R9: =IF(AND(Q9<=$Q$12+$Q$13,Q9>=$Q$12-$Q$13),Q9,"*") -> 11655.37
A10: Avaliando | B10: =AMOSTRAS!E5 -> Guaraí - TO | C10: AVALIANDA | G10: =AMOSTRAS!G14 -> 0.75109687 | I10: 1.1 | K10: 0.9 | M10: 1.2
A12: CCU Indexado¹ | C12: obtido da seguinte forma = (CCU imóvel Avaliando - CCU elmento da amostra) + 1 | P12: Média | Q12: =TRUNC(AVERAGE(Q4:Q9),2) -> 12704.2
A13: Situação Indexado ² | C13: obtido da seguinte forma = (Situação imóvel Avaliando - Situação elmento da amostra) + 1 | P13: Desvio Padrão | Q13: =TRUNC(IF(Q12="","",_xlfn.STDEV.S(Q4:Q9)),2) -> 1455.21
A14: =L3 -> Benfeitorias Indexado³ | C14: obtido da seguinte forma = (Distância imóvel Avaliando - Distância elmento da amostra) + 1 | P14: Limite Superior | Q14: =TRUNC(IF(Q12="","",Q12+Q13),2) -> 14159.41
A15: Hidrografia Indexado 4 | C15: obtido da seguinte forma = (Hidrografia imóvel Avaliando - Hidrografia elmento da amostra) + 1 | P15: Limite Inferior | Q15: =TRUNC(IF(Q12="","",Q12-Q13),2) -> 11248.99
A16: Fator Homogeneização Total (FHT) 6 | C16: Obtido pela multiplicação do CCU Indexado, da Situação Indexado, Distância Indexado, Hidrografia Indexado e Fator Oferta
A17: VT/ha homogeneizado 7 | C17: Resultado da multiplicação do VT / ha do elementdo da amostra pelo seu FHT | M17: n = | N17: 4 | P17: Média após Saneamento | Q17: =TRUNC(AVERAGE(R4:R9),2) -> 13189.81
A18: Limite Superior | C18: Limite superior de valor de VT/ha homogeneizado | M18: t = | N18: 0.271
A19: Limite Inferior | C19: Limite Inferior de valor de VT/ha homogeneizado | P19: Desvio Padrão Saneado | Q19: =TRUNC(_xlfn.STDEV.S(R4:R9),2) -> 937.24
A20: Amostra Saneada | C20: Elemento que apresente seu VT/ ha homogeneizado maior que o limite superior ou menor que o limite inferior | P20: Fator para I.C. | Q20: =TRUNC(N18*(Q19/(SQRT(N17))),2) -> 126.99
A21: Média após Saneamento | C21: Média de Valor calculado após eliminação dos elementos saneados | P21: I.C. Superior | Q21: =TRUNC(IF(Q17="","",Q17+Q20),2) -> 13316.8
A22: Fator para I.C. | C22: = t*(Desvio padrão saneado/ √ do numero de elementos utilizado), onde "t" é percentil da distribuição de Student, com grau de liberdade ( V = n-1) e 80% de confiança | P22: I.C. Inferior | Q22: =TRUNC(IF(Q17="","",Q17-Q20),2) -> 13062.82
A23: I.C. Superior | C23: Média Saneada + Fator para I.C. | P23: Amplitude | Q23: =TRUNC(IF(Q21="","",Q21-Q22),2) -> 253.98
A24: I.C. Inferior | C24: Média Saneada - Fator para I.C. | P24: Coeficiente de Variação % | Q24: =IF(Q17="","",(Q23/Q17)*100) -> 1.9255774
A25: Amplitude | C25: I.C. Superior - I.C. Inferior
A26: Coeficiente de Variação | C26: Amplitude / Média Saneada
P29: =Q17*4.84 -> 63838.68

Sheet SANEAMENTO
C4: ='AREA UTIL '!C4 -> MATRÍCULA 11.173
C5: SANEAMENTO DAS AMOSTRAS
C6: Desvio Padrão Saneado | F6: ='PLANILHA HOMOG'!Q19 -> 937.24
C7: Limite Superior (R$/ha) | F7: ='PLANILHA HOMOG'!Q14 -> 14159.41
C8: Limite Inferior (R$/ha) | F8: ='PLANILHA HOMOG'!Q15 -> 11248.99
C9: Elementos Saneados | F9: 6 | J9: PREENCHER MANUAL
C10: Elementos Expurgados | F10: 1 | J10: PREENCHER MANUAL
C11: Coeficiente de Variação % | F11: ='PLANILHA HOMOG'!Q24 -> 1.9255774
C12: T. Student | F12: ='PLANILHA HOMOG'!N18 -> 0.271
C13: Amplitude | F13: ='PLANILHA HOMOG'!Q23 -> 253.98
C14: Valor médio apurado (R$/ha) | F14: ='PLANILHA HOMOG'!Q17 -> 13189.81 | J14: =F14*4.84 -> 63838.68
C16: VALOR DE TERRA NUA APURADO
C17: Área total do imóvel avaliando | F17: =AMOSTRAS!E14 -> 52.0343
C18: Valor do hectare (R$/ha) | F18: ='PLANILHA HOMOG'!Q17 -> 13189.81
C19: Valor total de terra nua | F19: =F17*F18 -> 686322.53
C20: Valor adotado | F20: =F19 -> 686322.53
C24: VALOR DE BENFEITORIAS - PIVÔ CENTRAL + hidraulico
C25: Custo de de Formação (novo) | F25: 2000000
C26: Depreciação: Adequada/bom | F26: 0.8
C27: Valor depreciado | F27: =F25*F26 -> 1600000
C28: Valor adotado | F28: =F27 -> 1600000
C31: VALOR TOTAL DE TERRA NUA + BENFEITORIAS
C32: Valor Total de Terra Nua | F32: =F20 -> 686322.53
C33: Valor do Pivô | F33: =F28 -> 1600000
C34: Valor Total | F34: =F32+F33 -> 2286322.5

Sheet LIQUIDAÇÃO
C5: =SANEAMENTO!C4 -> MATRÍCULA 11.173
C6: CÁLCULO DE VALOR DE LIQUIDAÇÃO FORÇADA
C7: i - Taxa de Desconto | F7: 0.1325
C8: n - Número de meses | F8: 36
C9: Coeficiente Calculado | F9: =1/((1+F7)^(F8/12)) -> 0.68847055
C10: Valor de Mercado | F10: =SANEAMENTO!F20 -> 686322.53
C11: Valor de Liquidação Forçada | F11: =F10/((1+F7)^(F8/12)) -> 472512.85
C13: CÁLCULO DE VALOR DE LIQUIDAÇÃO FORÇADA
C14: i - Taxa de Desconto | F14: 0.12768
C15: n - Número de meses | F15: 36
C16: Coeficiente Calculado | F16: =1/((1+F14)^(F15/12)) -> 0.69733645
C17: Valor de Mercado | F17: =SANEAMENTO!F28 -> 1600000
C18: Valor de Liquidação Forçada | F18: =F17/((1+F14)^(F15/12)) -> 1115738.3

Sheet LAUDO DE AVALIAÇÃO
B2: LAUDO DE AVALIAÇÃO
B6: 014 - OBSERVAÇÕES DO AVALIADOR CÁLCULO DA TERRA NUA
W8: Avaliação Intervalar:
B9: Área avaliada (ha) | H9: x | I9: Valor homogeneizado / ha | W9: Estimativa de tendênia Central obtido
B10: =AMOSTRAS!E14 -> 52.0343 | H10: x | I10: =IF(B10=" ","",W11) -> 13189.81 | Q10: = | R10: =IF(B10=" ","",I10*B10) -> 686322.53 | W10: em planilha de Homogeneização.
W11: ='PLANILHA HOMOG'!Q17 -> 13189.81
O12: TOTAL | Q12: = | R12: =R10 -> 686322.53
B14: Outras áreas:
B15: Especificar Área (ha) | H15: x | I15: Valor homogeneizado / ha
H16: x | I16: =IF(B16=" ","",W11) | Q16: = | R16: =IF(B16=" ","",I16*B16)
O18: TOTAL | Q18: = | R18: =R16
B20: 015 - RESUMO DOS VALORES
B22: 15.1 - ÁREA AVALIADA................................................................................................................. | V22: R$ | W22: =R12 -> 686322.53
B23: 15.2 - OUTRAS ÁREAS - ESPECIFICAR................................................................................................................................... | V23: R$ | W23: =R16
B24: 15.3 - SUB-TOTAL (01)................................................................................................................................... | V24: R$ | W24: =SUM(W22:W23) -> 686322.53
B25: 15.4 - QUADRO 12.1 - CULTURAS PERMANENTES......................................................................................... | V25: R$ | W25: ='LAUDO DE AVALIAÇÃO 12-12.4'!H9 -> 0
B26: 15.5 - QUADRO 12.2 - CULTURAS TEMPORÁRIAS............................................................................................................................ | V26: R$ | W26: ='LAUDO DE AVALIAÇÃO 12-12.4'!H14 -> 0
B27: 15.6 - QUADRO 12.3 - PASTAGENS ARTIFICIAIS.................................................................................................................................. | V27: R$ | W27: ='LAUDO DE AVALIAÇÃO 12-12.4'!H19 -> 0
B28: 15.7 - QUADRO 12.4 - EXTRATIVISMO.................................................................................................................................. | V28: R$ | W28: ='LAUDO DE AVALIAÇÃO 12-12.4'!H24 -> 0
B29: 15.8 - QUADRO 13 - BENFEITORIAS NÃO REPRODUTIVAS.......................................................................................................... | V29: R$ | W29: ='LAUDO DE AVALIAÇÃO 13'!G8 -> 0
B30: 15.9 - SUB-TOTAL (02).................................................................................................................................. | V30: R$ | W30: =SUM(W25:Z29) -> 0
B31: 15.10 - TOTAL (1+2)................................................................................................................................................................ | V31: R$ | W31: =W30+W24 -> 686322.53
B32: 15.11 - MÊS BASE DA AVALIAÇÃO | K32: 43009
O33: Limite Inferior (estimativa -10%) | W33: Limite Superior (estimativa +10%)
Q34: =W31*0.9 -> 617690.28 | Y34: =W31*1.1 -> 754954.78

Sheet LAUDO DE AVALIAÇÃO 12-12.4
B1: LAUDO DE AVALIAÇÃO
B4: 12 - BENFEITORIAS REPRODUTIVAS
B5: 12.1 - CULTURAS PERMANENTES
B6: DISCRIMINAÇÃO (A) | C6: IDADE (B) | D6: ESTADO FITOSSANITÁRIO (C) | E6: UNIDADE (E) | F6: QUANTIDADE (D) | G6: VALORES EM REAIS
G7: UNITÁRIO | H7: TOTAL
H8: =TRUNC(F8*G8,2) -> 0
B9: TOTAL | H9: =TRUNC(SUM(H8:H8),2) -> 0
B10: 12.2 - CULTURAS TEMPORÁRIAS
B11: DISCRIMINAÇÃO (A) | C11: IDADE (B) | D11: ESTADO FITOSSANITÁRIO (C) | E11: UNIDADE © | F11: QUANTIDADE (D) | G11: VALORES EM REAIS
G12: UNITÁRIO | H12: TOTAL
H13: =TRUNC(F13*G13,2) -> 0
B14: TOTAL | H14: =TRUNC(SUM(H13:H13),2) -> 0
B15: 12.3 - PASTAGENS
B16: DISCRIMINAÇÃO (A) | C16: DEPRECIAÇÃO | D16: ESTADO FITOSSANITÁRIO (C) | E16: UNIDADE © | F16: QUANTIDADE (D) | G16: VALORES EM REAIS
G17: UNITÁRIO | H17: TOTAL
B18: area de pastagem andropólgon | H18: =TRUNC(F18*G18,2) -> 0
B19: TOTAL | H19: =TRUNC(SUM(H18:H18),2) -> 0
B20: 12.4 - EXTRATIVISMO
B21: DISCRIMINAÇÃO (A) | C21: IDADE (B) | D21: ESTADO FITOSSANITÁRIO (C) | E21: UNIDADE © | F21: QUANTIDADE (D) | G21: VALORES EM REAIS
G22: UNITÁRIO | H22: TOTAL
H23: =TRUNC(F23*G23,2) -> 0
B24: TOTAL

Sheet LAUDO DE AVALIAÇÃO 13
B1: LAUDO DE AVALIAÇÃO
B4: 13 - BENFEITORIAS NÃO REPRODUTIVAS
B5: DISCRIMINAÇÃO | C5: UNID. | D5: DEPREC. | E5: QUANT. | F5: VALOR EM R$ REAIS
F6: UNITÁRIO | G6: TOTAL
B8: TOTAL

Sheet quadro_resumo
A1: QUADRO RESUMO DA AVALIAÇÃO
A2: Proponente: | C2: Raimunda Laercia Dourado da Silva | J2: CPF: 577.518.031-34
A3: Proprietário: | C3: Raimunda Laercia Dourado da Silva | J3: CPF:577.518.031-34
A4: Agencia: | C4: UA Guaraí (18)
A5: Identificação: | C5: Fazenda Ypê
A6: Município: | C6: Guaraí | J6: UF: TO
A7: MAPA DA ÁREA
A31: IMOVEL
A32: Nº Matrícula | D32: Identificação | G32: Área há | J32: Área Construída m²
A33: 13157 | D33: fazenda | G33: 48.3293 | J33: 300
A34: VALORES
A35: Nº Matrícula | F35: Valor de mercado | K35: Liquidação forçada
A36: 13157 | F36: R$ 25.000.000,00 | K36: R$ 65.000.000,00
