Workbook

Sheet CAPA DO LAUDO
B3: LAUDO DE AVALIAÇÃO Nº 898992
B7: Proponente: | E7: Sivalto Pimental de Morais
B8: Processo: | E8: 898992
B9: Agência Solicitante: | E9: 14 - Porto Nacional
B10: Objetivo: | E10: Valor de mercado e de liquidação forçada para fins de garantia bancária
B11: Objeto: | E11: Lote n° 34 - G, loteamneto Mangues Gleba 1
B12: Local e Data: | E12: Palmas - TO, 10 de novembro de 2023
B17: QUADRO RESUMO DA AVALIAÇÃO
B19: Proponente: | E19: Sivalto Pimentel De Morais
B20: Agência Solicitante: | E20: 14 – Agência Porto Nacional
B21: Identificação: | E21: Lote n° 34 - G, Loteamento Mangues Gleba 1
B22: Município: | E22: Porto Nacional
B23: IMÓVEL
B24: Nº Matrícula | E24: Identificação | H24: Área Superficial há | K24: Área Construída m²
B25: 14664 | E25: Fazenda | H25: 101.64 | K25: 114
B27: CROQUI
B34: VALORES
B35: MATRÍCULA | F35: MERCADO R$ | J35: LIQUIDAÇÃO FORÇADA R$
B36: 14664
B38: TOTAL
B39: OBSERVAÇÕES

Sheet FATORES
D5: TOPOGRAFIA | E5: Fatores
D6: 0 a 2% (PLANO) | E6: 1.2
D7: 2 a 5% (SUAVE ONDULADO) | E7: 1.1
D8: 5 a 10 (MODERADAMENTE ONDULADO) | E8: 1
D9: 10 a 15% (ONDULADO) | E9: 0.9
D10: 15 a 45% (FORTE ONDULADO) | E10: 0.8
D11: 45 a 70% (MONTANHOSO) | E11: 0.7
D12: > 70% (ESCARPADO) | E12: 0.6
D13: FONTE: ARANTES (2017)
D17: HIDROGRAFIA
D18: 1,30 a 1,50 - (MUITO BOM) | E18: 1.2
D19: 1,15 a 1,29 - (BOM) | E19: 1.1
D20: 1,01 a 1,14 - (NORMAL) | E20: 1
D21: 1,00 - (REGULAR) | E21: 0.9
D22: 0,80 a 0,99 - (RUIM) | E22: 0.8
D23: 0,50 a 0,79 - (MUITO RUIM) | E23: 0.7
D25: FONTE: DESLANDES, CRISTIANO AUGUSTO - AVALIAÇÃO DE IMÓVEIS RURAIS (2002).
D26: FONTE: GLOSSÁRIO INTERNACIONAL DE HIDROLOGIA (UNESCO).
D29: BENFEITORIAS | E29: Fatores
D30: MUITO ACIMA DA MÉDIA | E30: 1.2
D31: ACIMA DA MÉDIA | E31: 1.1
D32: MÉDIA | E32: 1
D33: ABAIXO DA MÉDIA | E33: 0.9
D34: MUITO ABAIXO DA MÉDIA | E34: 0.8
D35: SEM BENFEITORIA | E35: 0.7
D40: Situação | E40: CARACTERÍSTICA
E41: Tipo de Estrada | F41: Trafegabilidade | G41: Fatores
D42: Ótima | E42: Pavimentada com asfalto/concreto | F42: Permanente | G42: 1.2
D43: Muito Boa | E43: Pavimentada com cascalhamento/intertravado | F43: Permanente | G43: 1.1
D44: Boa | E44: Não Pavimentada | F44: Permanente | G44: 1
D45: Desfavorável | E45: Não Pavimentada e Servidões de Passagem | F45: Problemas sérios nas Estações chuvosas | G45: 0.9
D46: Má | E46: Servidões com a presença de fechos | G46: 0.8
D47: Péssima | E47: Fechos e interceptados por córregos sem pontes | F47: Problemas sérios mesmo nas secas | G47: 0.7

Sheet AREA UTIL 
C4: =C16 -> MATRÍCULA 11.173
C5: AREA TOTAL | E5: AREA DE RESERVA | G5: AREA DE APP | I5: ÁREA CONSTRUÍDA
C6: 101.64 | E6: - | G6: - | I6: -
C7: CERTIFICADO DE CADASTRO DE IMÓVEL RURAL - CCIR
C8: AREA TOTAL | E8: CLASSIFICAÇÃO FUNDIÁRIA | G8: MÓDULO FISCAL | I8: Nº DE MÓDULOS FISCAIS
C9: 112.4828 | E9: Pequena Propriedade Produtiva | G9: 80 | I9: 1.406
C10: CADASTRO AMBIENTAL RURAL - CAR
C11: AREA TOTAL | E11: AREA DE RESERVA | G11: AREA DE APP | I11: ÁREA CONSOLIDADA
C12: 112.5586 | E12: 40.1032 | G12: 3.2536 | I12: 74.8272
C13: SITUAÇÃO | E13: Ativo | G13: CONDIÇÃO | I13: Aguardando análise
C16: MATRÍCULA 11.173
C17: USO DA TERRA | F17: ÁREA (ha) | H17: % ÁREA
C18: Área de Uso | F18: 63 | H18: =F18/C6 -> 0.61983471
C19: Área De Reserva Legal e APP | F19: 38.64 | H19: =F19/C6 -> 0.38016529
C20: SOMATÓRIA | F20: =SUM(F18:G19) -> 101.64 | H20: =SUM(H18:I19) -> 1

Sheet AMOSTRAS
B3: AVALIANDA
B4: Proprietário(s): | E4: Renato Borges Azevedo | G4: Contato: | H4: (63) 99217-9003
B5: Localização do Imóvel: | E5: Juarina - TO | G5: Situação: | H5: Boa
B6: Área do Imóvel (ha): | E6: 319.4464 | G6: Benfeitoria: | H6: Média
C7: Hidrografia: | E7: Normal | G7: Data: | H7: 45294
C8: Matrícula: | E8: 1499 | G8: Outros:
B9: Nota Agronômica da Amostra
B10: Classe de Solo | E10: Área (ha) | F10: % do Imóvel | G10: Nota Agronômica
B11: IV | E11: =E6-E12 -> 262.9242 | F11: =E11/E6 -> 0.82306202 | G11: 1
B12: VIII | E12: =28.486+28.0362 -> 56.5222 | F12: =E12/E6 -> 0.17693798 | G12: 0.6
B13: SOMATÓRIA | E13: =SUM(E11:E12) -> 319.4464 | F13: =SUM(F11:F12) -> 1 | G13: =(F12*G12)+F11*G11 -> 0.92922481
B15: Dado Amostral 01
B16: Proprietário / Informante: | E16: Ruraliza Negócios | G16: Contato: | H16: (63) 99252-2282 | K16: https://to.olx.com.br/tocantins/terrenos/fazenda-na-regiao-de-juarina-to-1015923530?lis=listing_1100
B17: Localização do Imóvel: | E17: Juarina - TO | G17: Situação: | H17: Boa
B18: Área do Imóvel (ha): | E18: 1780.9 | G18: Benfeitoria: | H18: Média
C19: Valor venal: | E19: 31000000 | G19: Valor R$/ha: | H19: =E19/E18 -> 17406.929
C20: Negociação: | E20: Oferta | G20: Data: | H20: 45294
C21: Hidrografia: | E21: Normal | G21: Outros:
B22: Nota Agronômica da Amostra
B23: Classe de Solo | E23: Área (ha) | F23: % do Imóvel | G23: Nota Agronômica
B24: IV | E24: =E18-E25 -> 1068.54 | F24: =E24/E18 -> 0.6 | G24: 1
B25: VIII | E25: =E18*0.4 -> 712.36 | F25: =E25/E18 -> 0.4 | G25: 0.6
B26: SOMATÓRIA | E26: =SUM(E24:E25) -> 1780.9 | F26: =SUM(F24:F25) -> 1 | G26: =F24*G24+F25*G25 -> 0.84
B28: Dado Amostral 02
B29: Proprietário / Informante: | E29: Ruraliza Negócios | G29: Contato: | H29: (63) 99252-2282 | K29: https://to.olx.com.br/tocantins/terrenos/fazenda--na-regiao-de-juarina-to-1088250640?lis=listing_1100
B30: Localização do Imóvel: | E30: Juarina - TO | G30: Situação: | H30: Boa
B31: Área do Imóvel (ha): | E31: 508.2 | G31: Benfeitoria: | H31: Média
C32: Valor venal: | E32: 8400000 | G32: Valor R$/ha: | H32: =E32/E31 -> 16528.926
C33: Negociação: | E33: Oferta | G33: Data: | H33: 45294
C34: Hidrografia: | E34: Regular | G34: Outros:
B35: Nota Agronômica da Amostra
B36: Classe de Solo | E36: Área (ha) | F36: % do Imóvel | G36: Nota Agronômica
C37: IV | E37: =E31-E38 -> 315.084 | F37: =E37/E31 -> 0.62 | G37: 1
B38: VIII | E38: =E31*0.38 -> 193.116 | F38: =E38/E31 -> 0.38 | G38: 0.6
B39: SOMATÓRIA | E39: =SUM(E37:E38) -> 508.2 | F39: =SUM(F37:F38) -> 1 | G39: =F38*G38+F37*G37 -> 0.848
B41: Dado Amostral 03
B42: Proprietário / Informante: | E42: MSC | G42: Contato: | H42: (62) 99432-5672 | K42: https://to.olx.com.br/tocantins/terrenos/fazenda-municipio-de-couto-magalhaes-tocantins-area-406-alqueires-1073165142?lis=listing_1100
B43: Localização do Imóvel: | E43: Couto Magalhães - TO | G43: Situação: | H43: Boa
B44: Área do Imóvel (ha): | E44: 1965.04 | G44: Benfeitoria: | H44: Média
C45: Valor venal: | E45: 44000000 | G45: Valor R$/ha: | H45: =E45/E44 -> 22391.402
...

Sheet QUADRO
B3: ELEMENTO | C3: ÁREA (ha) | D3: VT (R$) | E3: VT(R$/ha) | F3: CLASSE | G3: SITUAÇÃO | H3: BENFEITORIAS | I3: HIDROGRAFIA | J3: FONTE | K3: INFORMANTE | L3: CONTATO
B4: 1 | C4: =AMOSTRAS!E18 -> 1780.9 | D4: =AMOSTRAS!E19 -> 31000000 | E4: =D4/C4 -> 17406.929 | F4: =AMOSTRAS!G26 -> 0.84 | G4: 1 | H4: 1 | I4: 1 | J4: 0.9 | K4: =AMOSTRAS!E16 -> Ruraliza Negócios | L4: =AMOSTRAS!H16 -> (63) 99252-2282
B5: 2 | C5: =AMOSTRAS!E31 -> 508.2 | D5: =AMOSTRAS!E32 -> 8400000 | E5: =D5/C5 -> 16528.926 | F5: =AMOSTRAS!G39 -> 0.848 | G5: 1 | H5: 1 | I5: 1 | J5: 0.9 | K5: =AMOSTRAS!E29 -> Ruraliza Negócios | L5: =AMOSTRAS!H29 -> (63) 99252-2282
B6: 3 | C6: =AMOSTRAS!E44 -> 1965.04 | D6: =AMOSTRAS!E45 -> 44000000 | E6: =D6/C6 -> 22391.402 | F6: =AMOSTRAS!G52 -> 0.84 | G6: 1 | H6: 1 | I6: 1 | J6: 0.9 | K6: =AMOSTRAS!E42 -> MSC | L6: =AMOSTRAS!H42 -> (62) 99432-5672
B7: 4 | C7: =AMOSTRAS!E57 -> 1679.48 | D7: =AMOSTRAS!E58 -> 27460000 | E7: =D7/C7 -> 16350.299 | F7: =AMOSTRAS!G65 -> 0.844 | G7: 1 | H7: 1 | I7: 1 | J7: 0.9 | K7: =AMOSTRAS!E55 -> Ruraliza Negócios | L7: (63) 99968-05-68
B8: 5 | C8: =AMOSTRAS!E70 -> 980 | D8: =AMOSTRAS!E71 -> 20000000 | E8: =D8/C8 -> 20408.163 | F8: =AMOSTRAS!G78 -> 0.856 | G8: 1 | H8: 1 | I8: 1 | J8: 0.9 | K8: =AMOSTRAS!E68 -> Mil Fazendas | L8: 0
B9: 6 | C9: =AMOSTRAS!E83 -> 2105.4 | D9: =AMOSTRAS!E84 -> 36975000 | E9: =D9/C9 -> 17561.983 | F9: =AMOSTRAS!G91 -> 0.836 | G9: 1 | H9: 1 | I9: 1 | J9: 0.9 | K9: =AMOSTRAS!E81 -> José Geraldo Vieira | L9: =AMOSTRAS!H81 -> (38) 99821-6261

Sheet PLANILHA HOMOG
A3: Elemento | B3: Municipio | C3: Imóvel | D3: Valor do Imóvel R$ | E3: Área Total Do Imóvel (ha) | F3: Valor por hectare (R$/ha) | G3: CCU do Elemento | H3: CCU Indexado 1 | I3: Situação Elemento | J3: Situação Indexado² | K3: Benfeitorias | L3: Benfeitorias Indexado³ | M3: Hidrografia Elemento | N3: Hidrografia Indexado 4 | O3: Fator Oferta Elemento | P3: Fator Homogeneização Total (FHT) 6 | Q3: VT/ha homogeneizado 7 | R3: Amostra Saneada
A4: 1 | B4: =AMOSTRAS!E17 -> Juarina - TO | C4: Imóvel 1 | D4: =AMOSTRAS!E19 -> 31000000 | E4: =AMOSTRAS!E18 -> 1780.9 | F4: =D4/E4 -> 17406.929 | G4: =AMOSTRAS!G26 -> 0.84 | H4: =IF(G10=" ","",$G$10-G4+1) -> 1.0892248 | I4: =QUADRO!G4 -> 1 | J4: =IF(I10=" ","",$I$10-I4+1) -> 1 | K4: 1 | L4: =IF(K10=" ","",$K$10-K4+1) -> 1.1 | M4: 1 | N4: =IF(M10=" ","",$M$10-M4+1) -> 1 | O4: =QUADRO!J4 -> 0.9 | P4: =TRUNC(IF(O4=" ","",H4*J4*L4*N4*O4),4) -> 1.0783 | Q4: =TRUNC(IF(F4="","",F4*P4),2) -> 18769.89 | R4: =IF(AND(Q4<=$Q$12+$Q$13,Q4>=$Q$12-$Q$13),Q4,"*") -> 18769.89
A5: 2 | B5: =AMOSTRAS!E30 -> Juarina - TO | C5: Imóvel 2 | D5: =AMOSTRAS!E32 -> 8400000 | E5: =AMOSTRAS!E31 -> 508.2 | F5: =D5/E5 -> 16528.926 | G5: =AMOSTRAS!G39 -> 0.848 | H5: =IF(G10=" ","",$G$10-G5+1) -> 1.0812248 | I5: =QUADRO!G5 -> 1 | J5: =IF(I10=" ","",$I$10-I5+1) -> 1 | K5: 1 | L5: =IF(K10=" ","",$K$10-K5+1) -> 1.1 | M5: 1 | N5: =IF(M10=" ","",$M$10-M5+1) -> 1 | O5: =QUADRO!J5 -> 0.9 | P5: =TRUNC(IF(O5=" ","",H5*J5*L5*N5*O5),4) -> 1.0704 | Q5: =TRUNC(IF(F5="","",F5*P5),2) -> 17692.56 | R5: =IF(AND(Q5<=$Q$12+$Q$13,Q5>=$Q$12-$Q$13),Q5,"*") -> 17692.56
A6: 3 | B6: =AMOSTRAS!E43 -> Couto Magalhães - TO | C6: Imóvel 3 | D6: =AMOSTRAS!E45 -> 44000000 | E6: =AMOSTRAS!E44 -> 1965.04 | F6: =D6/E6 -> 22391.402 | G6: =AMOSTRAS!G52 -> 0.84 | H6: =IF(G10=" ","",$G$10-G6+1) -> 1.0892248 | I6: =QUADRO!G6 -> 1 | J6: =IF(I10=" ","",$I$10-I6+1) -> 1 | K6: 1 | L6: =IF(K10=" ","",$K$10-K6+1) -> 1.1 | M6: 1 | N6: =IF(M10=" ","",$M$10-M6+1) -> 1 | O6: =QUADRO!J6 -> 0.9 | P6: =TRUNC(IF(O6=" ","",H6*J6*L6*N6*O6),4) -> 1.0783 | Q6: =TRUNC(IF(F6="","",F6*P6),2) -> 24144.64 | R6: =IF(AND(Q6<=$Q$12+$Q$13,Q6>=$Q$12-$Q$13),Q6,"*") -> *
A7: 4 | B7: =AMOSTRAS!E56 -> Couto Magalhães - TO | C7: Imóvel 4 | D7: =AMOSTRAS!E58 -> 27460000 | E7: =AMOSTRAS!E57 -> 1679.48 | F7: =D7/E7 -> 16350.299 | G7: =AMOSTRAS!G65 -> 0.844 | H7: =IF(G11=" ","",$G$10-G7+1) -> 1.0852248 | I7: =QUADRO!G7 -> 1 | J7: =IF(I11=" ","",$I$10-I7+1) -> 1 | K7: 1 | L7: =IF(K11=" ","",$K$10-K7+1) -> 1.1 | M7: 1 | N7: =IF(M11=" ","",$M$10-M7+1) -> 1 | O7: =QUADRO!J7 -> 0.9 | P7: =TRUNC(IF(O7=" ","",H7*J7*L7*N7*O7),4) -> 1.0743 | Q7: =TRUNC(IF(F7="","",F7*P7),2) -> 17565.12 | R7: =IF(AND(Q7<=$Q$12+$Q$13,Q7>=$Q$12-$Q$13),Q7,"*") -> 17565.12
A8: 5 | B8: =AMOSTRAS!E69 -> Pequizeiro - TO | C8: Imóvel 5 | D8: =AMOSTRAS!E71 -> 20000000 | E8: =AMOSTRAS!E70 -> 980 | F8: =D8/E8 -> 20408.163 | G8: =AMOSTRAS!G78 -> 0.856 | H8: =IF(G12=" ","",$G$10-G8+1) -> 1.0732248 | I8: =QUADRO!G8 -> 1 | J8: =IF(I12=" ","",$I$10-I8+1) -> 1 | K8: 1 | L8: =IF(K12=" ","",$K$10-K8+1) -> 1.1 | M8: 1 | N8: =IF(M12=" ","",$M$10-M8+1) -> 1 | O8: =QUADRO!J8 -> 0.9 | P8: =TRUNC(IF(O8=" ","",H8*J8*L8*N8*O8),4) -> 1.0624 | Q8: =TRUNC(IF(F8="","",F8*P8),2) -> 21681.63 | R8: =IF(AND(Q8<=$Q$12+$Q$13,Q8>=$Q$12-$Q$13),Q8,"*") -> 21681.63
A9: 6 | B9: =AMOSTRAS!E82 -> Pequizeiro - TO | C9: Imóvel 6 | D9: =AMOSTRAS!E84 -> 36975000 | E9: =AMOSTRAS!E83 -> 2105.4 | F9: =D9/E9 -> 17561.983 | G9: =AMOSTRAS!G91 -> 0.836 | H9: =IF(G13=" ","",$G$10-G9+1) -> 1.0932248 | I9: =QUADRO!G9 -> 1 | J9: =IF(I13=" ","",$I$10-I9+1) -> 1 | K9: 1 | L9: =IF(K13=" ","",$K$10-K9+1) -> 1.1 | M9: 1 | N9: =IF(M13=" ","",$M$10-M9+1) -> 1 | O9: =QUADRO!J9 -> 0.9 | P9: =TRUNC(IF(O9=" ","",H9*J9*L9*N9*O9),4) -> 1.0822 | Q9: =TRUNC(IF(F9="","",F9*P9),2) -> 19005.57 | R9: =IF(AND(Q9<=$Q$12+$Q$13,Q9>=$Q$12-$Q$13),Q9,"*") -> 19005.57
A10: Avaliando | B10: =AMOSTRAS!E5 -> Juarina - TO | C10: AVALIANDA | G10: =AMOSTRAS!G13 -> 0.92922481 | I10: 1 | K10: 1.1 | M10: 1
A12: CCU Indexado¹ | C12: obtido da seguinte forma = (CCU imóvel Avaliando - CCU elmento da amostra) + 1 | P12: Média | Q12: =TRUNC(IF(Q4="","",AVERAGE(Q4:Q9)),2) -> 19809.9
A13: Situação Indexado ² | C13: obtido da seguinte forma = (Situação imóvel Avaliando - Situação elmento da amostra) + 1 | P13: Desvio Padrão | Q13: =TRUNC(IF(Q12="","",_xlfn.STDEV.S(Q4:Q9)),2) -> 2590.13
A14: =L3 -> Benfeitorias Indexado³ | C14: obtido da seguinte forma = (Distância imóvel Avaliando - Distância elmento da amostra) + 1 | P14: Limite Superior | Q14: =TRUNC(IF(Q12="","",Q12+Q13),2) -> 22400.03
A15: Hidrografia Indexado 4 | C15: obtido da seguinte forma = (Hidrografia imóvel Avaliando - Hidrografia elmento da amostra) + 1 | P15: Limite Inferior | Q15: =TRUNC(IF(Q12="","",Q12-Q13),2) -> 17219.77
A16: Fator Homogeneização Total (FHT) 6 | C16: Obtido pela multiplicação do CCU Indexado, da Situação Indexado, Distância Indexado, Hidrografia Indexado e Fator Oferta
A17: VT/ha homogeneizado 7 | C17: Resultado da multiplicação do VT / ha do elementdo da amostra pelo seu FHT | M17: n = | N17: 4 | P17: Média após Saneamento | Q17: =TRUNC(AVERAGE(R4:R9),2) -> 18942.95
A18: Limite Superior | C18: Limite superior de valor de VT/ha homogeneizado | M18: t = | N18: 0.267
A19: Limite Inferior | C19: Limite Inferior de valor de VT/ha homogeneizado | P19: Desvio Padrão Saneado | Q19: =TRUNC(_xlfn.STDEV.S(R4:R9),2) -> 1658.02
A20: Amostra Saneada | C20: Elemento que apresente seu VT/ ha homogeneizado maior que o limite superior ou menor que o limite inferior | P20: Fator para I.C. | Q20: =TRUNC(N18*(Q19/(SQRT(N17))),2) -> 221.34
A21: Média após Saneamento | C21: Média de Valor calculado após eliminação dos elementos saneados | P21: I.C. Superior | Q21: =TRUNC(IF(Q17="","",Q17+Q20),2) -> 19164.29
A22: Fator para I.C. | C22: = t*(Desvio padrão saneado/ √ do numero de elementos utilizado), onde "t" é percentil da distribuição de Student, com grau de liberdade ( V = n-1) e 80% de confiança | P22: I.C. Inferior | Q22: =TRUNC(IF(Q17="","",Q17-Q20),2) -> 18721.61
A23: I.C. Superior | C23: Média Saneada + Fator para I.C. | P23: Amplitude | Q23: =TRUNC(IF(Q21="","",Q21-Q22),2) -> 442.68
A24: I.C. Inferior | C24: Média Saneada - Fator para I.C. | P24: Coeficiente de Variação % | Q24: =IF(Q17="","",(Q23/Q17)*100) -> 2.3369116
A25: Amplitude | C25: I.C. Superior - I.C. Inferior
A26: Coeficiente de Variação | C26: Amplitude / Média Saneada

Sheet SANEAMENTO
C4: SANEAMENTO DAS AMOSTRAS
C5: Desvio Padrão Saneado | F5: ='PLANILHA HOMOG'!Q19 -> 1658.02
C6: Limite Superior (R$/ha) | F6: ='PLANILHA HOMOG'!Q14 -> 22400.03
C7: Limite Inferior (R$/ha) | F7: ='PLANILHA HOMOG'!Q15 -> 17219.77
C8: Elementos Saneados | F8: 6 | J8: PREENCHER MANUAL
C9: Elementos Expurgados | F9: 1 | J9: PREENCHER MANUAL
C10: Coeficiente de Variação % | F10: ='PLANILHA HOMOG'!Q24 -> 2.3369116
C11: T. Student | F11: ='PLANILHA HOMOG'!N18 -> 0.267
C12: Amplitude | F12: ='PLANILHA HOMOG'!Q23 -> 442.68
C13: Valor médio apurado (R$/ha) | F13: ='PLANILHA HOMOG'!Q17 -> 18942.95 | J13: =F13*4.84 -> 91683.878
C15: VALOR DE TERRA NUA APURADO
C16: Área total do imóvel avaliando | F16: =AMOSTRAS!E13 -> 319.4464
C17: Valor do hectare (R$/ha) | F17: ='PLANILHA HOMOG'!Q17 -> 18942.95
C18: Valor total de terra nua | F18: =F16*F17 -> 6051257.2
C19: Valor adotado | F19: =F18 -> 6051257.2
C23: VALOR DE BENFEITORIAS - PIVÔ CENTRAL + hidraulico
C24: Custo de de Formação (novo) | F24: 2000000
C25: Depreciação: Adequada/bom | F25: 0.8
C26: Valor depreciado | F26: =F24*F25 -> 1600000
C27: Valor adotado | F27: =F26 -> 1600000
C30: VALOR TOTAL DE TERRA NUA + BENFEITORIAS
C31: Valor Total de Terra Nua | F31: =F19 -> 6051257.2
C32: Valor do Pivô | F32: =F27 -> 1600000
C33: Valor Total | F33: =F31+F32 -> 7651257.2

Sheet LIQUIDAÇÃO
C6: CÁLCULO DE VALOR DE LIQUIDAÇÃO FORÇADA
C7: i - Taxa de Desconto | F7: 0.1175
C8: n - Número de meses | F8: 24
C9: Coeficiente Calculado | F9: =1/((1+F7)^(F8/12)) -> 0.80076473
C10: Valor de Mercado | F10: =SANEAMENTO!F18 -> 6051257.2
C11: Valor de Liquidação Forçada | F11: =F10/((1+F7)^(F8/12)) -> 4845633.3
C13: CÁLCULO DE VALOR DE LIQUIDAÇÃO FORÇADA
C14: i - Taxa de Desconto | F14: 0.12768
C15: n - Número de meses | F15: 36
C16: Coeficiente Calculado | F16: =1/((1+F14)^(F15/12)) -> 0.69733645
C17: Valor de Mercado | F17: =SANEAMENTO!F27 -> 1600000
C18: Valor de Liquidação Forçada | F18: =F17/((1+F14)^(F15/12)) -> 1115738.3

Sheet LAUDO DE AVALIAÇÃO
B2: LAUDO DE AVALIAÇÃO
B6: 014 - OBSERVAÇÕES DO AVALIADOR CÁLCULO DA TERRA NUA
W8: Avaliação Intervalar:
B9: Área avaliada (ha) | H9: x | I9: Valor homogeneizado / ha | W9: Estimativa de tendênia Central obtido
H10: x | I10: =IF(B10=" ","",W11) -> 18942.95 | Q10: = | R10: =IF(B10=" ","",I10*B10) -> 0 | W10: em planilha de Homogeneização.
W11: ='PLANILHA HOMOG'!Q17 -> 18942.95
O12: TOTAL | Q12: = | R12: =R10 -> 0
B14: Outras áreas:
B15: Especificar Área (ha) | H15: x | I15: Valor homogeneizado / ha
H16: x | I16: =IF(B16=" ","",W11) | Q16: = | R16: =IF(B16=" ","",I16*B16)
O18: TOTAL | Q18: = | R18: =R16
B20: 015 - RESUMO DOS VALORES
B22: 15.1 - ÁREA AVALIADA................................................................................................................. | V22: R$ | W22: =R12 -> 0
B23: 15.2 - OUTRAS ÁREAS - ESPECIFICAR................................................................................................................................... | V23: R$ | W23: =R16
B24: 15.3 - SUB-TOTAL (01)................................................................................................................................... | V24: R$ | W24: =SUM(W22:W23) -> 0
B25: 15.4 - QUADRO 12.1 - CULTURAS PERMANENTES......................................................................................... | V25: R$ | W25: ='LAUDO DE AVALIAÇÃO 12-12.4'!H9 -> 0
B26: 15.5 - QUADRO 12.2 - CULTURAS TEMPORÁRIAS............................................................................................................................ | V26: R$ | W26: ='LAUDO DE AVALIAÇÃO 12-12.4'!H14 -> 0
B27: 15.6 - QUADRO 12.3 - PASTAGENS ARTIFICIAIS.................................................................................................................................. | V27: R$ | W27: ='LAUDO DE AVALIAÇÃO 12-12.4'!H19 -> 0
B28: 15.7 - QUADRO 12.4 - EXTRATIVISMO.................................................................................................................................. | V28: R$ | W28: ='LAUDO DE AVALIAÇÃO 12-12.4'!H24 -> 0
B29: 15.8 - QUADRO 13 - BENFEITORIAS NÃO REPRODUTIVAS.......................................................................................................... | V29: R$ | W29: ='LAUDO DE AVALIAÇÃO 13'!G8 -> 0
B30: 15.9 - SUB-TOTAL (02).................................................................................................................................. | V30: R$ | W30: =SUM(W25:Z29) -> 0
B31: 15.10 - TOTAL (1+2)................................................................................................................................................................ | V31: R$ | W31: =W30+W24 -> 0
B32: 15.11 - MÊS BASE DA AVALIAÇÃO | K32: 43009
O33: Limite Inferior (estimativa -10%) | W33: Limite Superior (estimativa +10%)
Q34: =W31*0.9 -> 0 | Y34: =W31*1.1 -> 0

Sheet LAUDO DE AVALIAÇÃO 12-12.4
B1: LAUDO DE AVALIAÇÃO
B4: 12 - BENFEITORIAS REPRODUTIVAS
B5: 12.1 - CULTURAS PERMANENTES
B6: DISCRIMINAÇÃO (A) | C6: IDADE (B) | D6: ESTADO FITOSSANITÁRIO (C) | E6: UNIDADE (E) | F6: QUANTIDADE (D) | G6: VALORES EM REAIS
G7: UNITÁRIO | H7: TOTAL
H8: =TRUNC(F8*G8,2) -> 0
B9: TOTAL | H9: =TRUNC(SUM(H8:H8),2) -> 0
B10: 12.2 - CULTURAS TEMPORÁRIAS
B11: DISCRIMINAÇÃO (A) | C11: IDADE (B) | D11: ESTADO FITOSSANITÁRIO (C) | E11: UNIDADE © | F11: QUANTIDADE (D) | G11: VALORES EM REAIS
G12: UNITÁRIO | H12: TOTAL
H13: =TRUNC(F13*G13,2) -> 0
B14: TOTAL | H14: =TRUNC(SUM(H13:H13),2) -> 0
B15: 12.3 - PASTAGENS
B16: DISCRIMINAÇÃO (A) | C16: DEPRECIAÇÃO | D16: ESTADO FITOSSANITÁRIO (C) | E16: UNIDADE © | F16: QUANTIDADE (D) | G16: VALORES EM REAIS
G17: UNITÁRIO | H17: TOTAL
B18: area de pastagem andropólgon | H18: =TRUNC(F18*G18,2) -> 0
B19: TOTAL | H19: =TRUNC(SUM(H18:H18),2) -> 0
B20: 12.4 - EXTRATIVISMO
B21: DISCRIMINAÇÃO (A) | C21: IDADE (B) | D21: ESTADO FITOSSANITÁRIO (C) | E21: UNIDADE © | F21: QUANTIDADE (D) | G21: VALORES EM REAIS
G22: UNITÁRIO | H22: TOTAL
H23: =TRUNC(F23*G23,2) -> 0
B24: TOTAL

Sheet LAUDO DE AVALIAÇÃO 13
B1: LAUDO DE AVALIAÇÃO
B4: 13 - BENFEITORIAS NÃO REPRODUTIVAS
B5: DISCRIMINAÇÃO | C5: UNID. | D5: DEPREC. | E5: QUANT. | F5: VALOR EM R$ REAIS
F6: UNITÁRIO | G6: TOTAL
B8: TOTAL
